Workbook
Name AA: '[1]Library SLL'!$A$15:$A$24
Name AA: '[1]Library SLL'!$A$15:$A$24
Name AA: '[1]Library SLL'!$A$15:$A$24
Name assoc: 'Library SLL'!$S$2:$S$12
Name bit: 'Library SLL'!$A$15:$A$24
Name casing_size: 'Library SLL'!$A$42:$A$44
Name casing_type: 'Library SLL'!$A$38:$A$40
Name check: '[2]Library Collar'!$G$16:$G$26
Name check: #REF!
Name check: #REF!
Name coal: 'Library SLL'!$D$12:$D$18
Name color: 'Library SLL'!$G$46:$G$54
Name cont: 'Library SLL'!$A$35:$A$36
Name core: 'Library SLL'!$A$32:$A$33
Name d_cont: '[2]Library Collar'!$D$2:$D$4
Name d_cont: #REF!
Name d_cont: #REF!
Name d_from: #REF!
Name d_from: SLL_Reconciled!$G$10:$G$879
Name d_from: SLL_Reconciled!$G$10:$G$879
Name d_rig: '[2]Library Collar'!$D$6:$D$10
Name d_rig: #REF!
Name d_rig: #REF!
Name d_rigid: '[2]Library Collar'!$D$12:$D$26
Name d_rigid: #REF!
Name d_rigid: #REF!
Name d_to: #REF!
Name d_to: SLL_Reconciled!$H$10:$H$879
Name d_to: SLL_Reconciled!$H$10:$H$879
Name data: #REF!
Name data: SLL_Reconciled!$H$10:$AQ$49879
Name data: SLL_Reconciled!$H$10:$AQ$49879
Name date: [2]SLL_WellCad!$AT$10:$AT$49906
Name date: SLL_Reconciled!$AT$10:$AT$49879
Name date: SLL_Reconciled!$AT$10:$AT$49879
Name date_from: [2]Collar!$I$5
Name date_from: Collar!$I$5
Name date_from: Collar!$I$5
Name date_to: [2]Collar!#REF!
Name date_to: Collar!#REF!
Name date_to: Collar!#REF!
Name day: 'Library SLL'!$A$2:$A$3
Name driller: '[2]Library SLL'!$V$2:$V$60
Name driller: 'Library SLL'!#REF!
Name driller: 'Library SLL'!#REF!
Name fosil: 'Library SLL'!$P$25:$P$28
Name fosil_abund: 'Library SLL'!$P$25:$P$28
Name fosil_min: 'Library SLL'!$P$30:$P$49
Name g_log: '[2]Library Collar'!$G$12:$G$14
Name g_log: #REF!
Name g_log: #REF!
Name gp_cont: '[2]Library Collar'!$G$2:$G$4
Name gp_cont: #REF!
Name gp_cont: #REF!
Name gp_log: '[2]Library Collar'!$G$6:$G$10
Name gp_log: #REF!
Name gp_log: #REF!
Name grain: 'Library SLL'!$J$2:$J$10
Name hole: #REF!
Name hole: SLL_Reconciled!$F$10:$F$49879

Sheet SLL_Wellsite
A2: PT. BUDI GEMA GEMPITA
A3: Sedimentary Lithology Log
A5: Prospect Area | C5: : BGG Block 1
A7: Hole_ID | B7: Drill Detail | Q7: Lithology | AU7: Comments
B8: Shift | C8: Log Basis | D8: Bit Type | E8: Hole Dia | F8: Continuity | G8: Depth | I8: Core Length | J8: Core Recov | K8: Core Loss | M8: Casing Type | N8: Casing Depth | O8: Casing Size | P8: Driller | Q8: Lith | R8: Lith Qualifier | S8: Colour | V8: Textur | AA8: Bedding | AD8: Sed Strc | AF8: Tectonic Structure | AJ8: Mech State | AK8: Strength | AL8: Weath | AM8: Min & Fosil | AN8: Abundance | AO8: Association | AP8: Sedim Relat | AQ8: Seam | AR8: Ply | AS8: Wellsite | AT8: Date Drilling
G9: From | H9: To | K9: From | L9: To | S9: Shade | T9: Hue | U9: Color | V9: Grain | W9: Round | X9: Sorting | Y9: Porosity | Z9: Perm | AA9: Spacing | AB9: Separt | AC9: Dip | AD9: Descript | AE9: Dip | AF9: Type | AG9: Spacing | AH9: Descript | AI9: Dip
A10: - | B10: - | C10: - | D10: - | E10: - | F10: - | G10: - | H10: - | P10: - | Q10: - | S10: - | T10: - | U10: - | AK10: - | AL10: - | AS10: - | AT10: -
A11: DH11_01 | B11: D | C11: A | D11: W | E11: HQ | F11: OH | G11: 0 | H11: 3 | P11: NRL | Q11: SO | R11: MD | S11: A | U11: B | AK11: R1 | AL11: DE | AS11: BSW | AT11: 43924
B12: D | C12: A | D12: W | E12: HQ | F12: OH | G12: 3 | H12: 27.5 | P12: NRL | Q12: SS | S12: A | U12: G | V12: FN | AK12: R3 | AL12: FR | AS12: BSW | AT12: 43924
B13: D | C13: A | D13: W | E13: HQ | F13: OH | G13: 27.5 | H13: 29 | P13: NRL | Q13: CO | U13: K | AK13: R4 | AL13: FR | AQ13: S7 | AS13: BSW | AT13: 43924
B14: D | C14: A | D14: W | E14: HQ | F14: OH | G14: 29 | H14: 41 | P14: NRL | Q14: CS | U14: G | AK14: R4 | AL14: FR | AS14: BSW | AT14: 43925
B15: D | C15: A | D15: W | E15: HQ | F15: OH | G15: 41 | H15: 42 | P15: NRL | Q15: XM | R15: TC | S15: C | U15: B | AK15: R4 | AL15: FR | AS15: BSW | AT15: 43925
B16: D | C16: A | D16: W | E16: HQ | F16: OH | G16: 42 | H16: 43 | P16: NRL | Q16: CO | U16: K | AK16: R4 | AL16: FR | AQ16: S7A | AS16: BSW | AT16: 43925
B17: D | C17: A | D17: W | E17: HQ | F17: OH | G17: 43 | H17: 59 | P17: NRL | Q17: CS | U17: G | AK17: R4 | AL17: FR | AS17: BSW | AT17: 43925
B18: D | C18: A | D18: W | E18: HQ | F18: OH | G18: 59 | H18: 62 | P18: NRL | Q18: CO | U18: K | AK18: R4 | AL18: FR | AQ18: S7B | AS18: BSW | AT18: 43925
B19: D | C19: A | D19: W | E19: HQ | F19: OH | G19: 62 | H19: 80 | P19: NRL | Q19: CS | U19: G | AK19: R4 | AL19: FR | AS19: BSW | AT19: 43926
B20: D | C20: A | D20: W | E20: HQ | F20: OH | G20: 80 | H20: 81 | P20: NRL | Q20: CO | U20: K | AK20: R4 | AL20: FR | AQ20: S7C | AS20: BSW | AT20: 43927
B21: D | C21: A | D21: W | E21: HQ | F21: OH | G21: 81 | H21: 86 | P21: NRL | Q21: CS | U21: G | AK21: R4 | AL21: FR | AS21: BSW | AT21: 43927
B22: D | C22: A | D22: W | E22: HQ | F22: OH | G22: 86 | H22: 88 | P22: NRL | Q22: CO | U22: K | AK22: R4 | AL22: FR | AQ22: S7D | AS22: BSW | AT22: 43927
B23: D | C23: A | D23: W | E23: HQ | F23: OH | G23: 88 | H23: 100 | P23: NRL | Q23: CS | U23: G | AK23: R4 | AL23: FR | AS23: BSW | AT23: 43927

Sheet SLL_Reconciled
A2: PT. BUDI GEMA GEMPITA
A3: Sedimentary Lithology Log
A5: Prospect Area | C5: : BGG Block Kungkilan
A7: Hole_ID | B7: Drill Detail | Q7: Lithology | AU7: Comments
B8: Shift | C8: Log Basis | D8: Bit Type | E8: Hole Dia | F8: Hole Type | G8: Depth | I8: Core Length | J8: Core Recov | K8: Core Loss | M8: Casing Type | N8: Casing Depth | O8: Casing Size | P8: Driller | Q8: Lith | R8: Lith Qualifier | S8: Colour | V8: Textur | AA8: Bedding | AD8: Sed Strc | AF8: Tectonic Structure | AJ8: Mech State | AK8: Strength | AL8: Weath | AM8: Min & Fosil | AN8: Abundance | AO8: Association | AP8: Sedim Relat | AQ8: Seam | AR8: Ply | AS8: Wellsite | AT8: Date Logged
G9: From | H9: To | K9: From | L9: To | S9: Shade | T9: Hue | U9: Color | V9: Grain | W9: Round | X9: Sorting | Y9: Porosity | Z9: Perm | AA9: Spacing | AB9: Separt | AC9: Dip | AD9: Descript | AE9: Dip | AF9: Type | AG9: Spacing | AH9: Descript | AI9: Dip
A10: - | B10: - | C10: - | D10: - | E10: - | F10: - | G10: - | H10: - | P10: - | Q10: - | S10: - | T10: - | U10: - | AK10: - | AL10: - | AS10: - | AT10: -
A11: DH11_01 | B11: D | C11: X | D11: W | E11: HQ | F11: OH | G11: 0 | H11: 3 | P11: NRL | Q11: SO | R11: MD | S11: A | U11: B | AK11: R1 | AL11: DE | AS11: BSW | AT11: 43924
B12: D | C12: X | D12: W | E12: HQ | F12: OH | G12: 3 | H12: 27.5 | P12: NRL | Q12: SS | S12: A | U12: G | V12: FN | AK12: R3 | AL12: FR | AS12: BSW | AT12: 43924
B13: D | C13: X | D13: W | E13: HQ | F13: OH | G13: 27.5 | H13: 27.62 | P13: NRL | Q13: CS | U13: G | AK13: R4 | AL13: FR | AS13: BSW | AT13: 43924
B14: D | C14: X | D14: W | E14: HQ | F14: OH | G14: 27.62 | H14: 28.6 | P14: NRL | Q14: CO | U14: K | AK14: R4 | AL14: FR | AQ14: S7 | AS14: BSW | AT14: 43924
B15: D | C15: X | D15: W | E15: HQ | F15: OH | G15: 28.6 | H15: 28.65 | P15: NRL | Q15: CS | U15: G | AK15: R4 | AL15: FR | AQ15: PA | AS15: BSW | AT15: 43924
B16: D | C16: X | D16: W | E16: HQ | F16: OH | G16: 28.65 | H16: 29.2 | P16: NRL | Q16: CO | U16: K | AK16: R4 | AL16: FR | AQ16: S7 | AS16: BSW | AT16: 43924
B17: D | C17: X | D17: W | E17: HQ | F17: OH | G17: 29.2 | H17: 41.4 | P17: NRL | Q17: CS | U17: G | AK17: R4 | AL17: FR | AS17: BSW | AT17: 43925
B18: D | C18: X | D18: W | E18: HQ | F18: OH | G18: 41.4 | H18: 41.85 | P18: NRL | Q18: XM | R18: TC | S18: C | U18: B | AK18: R4 | AL18: FR | AS18: BSW | AT18: 43925
B19: D | C19: X | D19: W | E19: HQ | F19: OH | G19: 41.85 | H19: 43.45 | P19: NRL | Q19: CO | U19: K | AK19: R4 | AL19: FR | AQ19: S7A | AS19: BSW | AT19: 43925
B20: D | C20: X | D20: W | E20: HQ | F20: OH | G20: 43.45 | H20: 58.92 | P20: NRL | Q20: CS | U20: G | AK20: R4 | AL20: FR | AS20: BSW | AT20: 43925
B21: D | C21: X | D21: W | E21: HQ | F21: OH | G21: 58.92 | H21: 60.25 | P21: NRL | Q21: CO | U21: K | AK21: R4 | AL21: FR | AQ21: S7B | AS21: BSW | AT21: 43925
B22: D | C22: X | D22: W | E22: HQ | F22: OH | G22: 60.25 | H22: 60.45 | P22: NRL | Q22: CS | U22: G | AK22: R4 | AL22: FR | AS22: BSW | AT22: 43925
B23: D | C23: X | D23: W | E23: HQ | F23: OH | G23: 60.45 | H23: 61.4 | P23: NRL | Q23: CO | U23: K | AK23: R4 | AL23: FR | AQ23: S7B | AS23: BSW | AT23: 43926
B24: D | C24: X | D24: W | E24: HQ | F24: OH | G24: 61.4 | H24: 61.45 | P24: NRL | Q24: CS | U24: G | AK24: R4 | AL24: FR | AS24: BSW | AT24: 43926
B25: D | C25: X | D25: W | E25: HQ | F25: OH | G25: 61.45 | H25: 62.05 | P25: NRL | Q25: CO | U25: K | AK25: R4 | AL25: FR | AQ25: S7B | AS25: BSW | AT25: 43926
B26: D | C26: X | D26: W | E26: HQ | F26: OH | G26: 62.05 | H26: 73.2 | P26: NRL | Q26: CS | U26: G | AK26: R4 | AL26: FR | AS26: BSW | AT26: 43926
B27: D | C27: X | D27: W | E27: HQ | F27: OH | G27: 73.2 | H27: 73.4 | P27: NRL | Q27: XM | R27: TC | S27: C | U27: B | AK27: R4 | AL27: FR | AS27: BSW | AT27: 43926
B28: D | C28: X | D28: W | E28: HQ | F28: OH | G28: 73.4 | H28: 77 | P28: NRL | Q28: CS | R28: SA | U28: G | AK28: R4 | AL28: FR | AS28: BSW | AT28: 43926
B29: D | C29: X | D29: W | E29: HQ | F29: OH | G29: 77 | H29: 80.05 | P29: NRL | Q29: CS | U29: G | AK29: R4 | AL29: FR | AS29: BSW | AT29: 43926
B30: D | C30: X | D30: W | E30: HQ | F30: OH | G30: 80.05 | H30: 81.08 | P30: NRL | Q30: CO | U30: K | AK30: R4 | AL30: FR | AQ30: S7C | AS30: BSW | AT30: 43927
B31: D | C31: X | D31: W | E31: HQ | F31: OH | G31: 81.08 | H31: 85.65 | P31: NRL | Q31: CS | U31: G | AK31: R4 | AL31: FR | AS31: BSW | AT31: 43927
B32: D | C32: X | D32: W | E32: HQ | F32: OH | G32: 85.65 | H32: 87.6 | P32: NRL | Q32: CO | U32: K | AK32: R4 | AL32: FR | AQ32: S7D | AS32: BSW | AT32: 43927
B33: D | C33: X | D33: W | E33: HQ | F33: OH | G33: 87.6 | H33: 100 | P33: NRL | Q33: CS | U33: G | AK33: R4 | AL33: FR | AS33: BSW | AT33: 43927

Sheet Collar
A2: Hole ID | B2: Collar | I2: Drilling | Q2: Geophysical | X2: Etc | AB2: Comments
B3: Coordinate | E3: Survey | I3: Date | K3: Drilling Contrac | L3: Rig Type | M3: Rig Number | N3: Driller | O3: Well Site | P3: Max Depth | Q3: Company | R3: Logger | S3: Geophysical Log | W3: Max Depth | X3: Surface Water | Z3: Entered By | AA3: Checked By
B4: East | C4: North | D4: RL | E4: Date | F4: Company | G4: Method | H4: Surveyor | I4: From | J4: To | S4: GM | T4: DN | U4: CAL | V4: RS | X4: Date | Y4: Depth
A5: DH11_01 | B5: 359619.03 | C5: 9590558 | D5: 69.816 | E5: 0 | F5: BGG | G5: TS | H5: - | I5: 43924 | J5: 43928 | K5: AAS | L5: Jacro175 | M5: 02 | N5: NRL | O5: IMP | P5: 100 | Q5: REC | R5: WRH | S5: v | T5: v | U5: x | V5: x | W5: 95.98 | AA5: BSW

Sheet BHC
A2: PT. BUDI GEMA GEMPITA
A3: BORE HOLE COMPLETION
A5: Prospect Area | C5: : BGG Block 1
A7: NO | B7: HOLE NUMBER | D7: DATE | F7: LINE | G7: MACHINE | I7: COORDINATE BY GPS | L7: COORDINATE BY TS | O7: DRILLING | V7: CORE LENGTH ( M ) | W7: CORE REC. ( % ) | X7: TOTAL DEPTH (m) | Z7: COAL INTERVAL | AF7: PICKING FROM | AG7: RECONCILE | AJ7: COAL REC ( % ) | AK7: SEAM | AL7: SAMPLE ID | AM7: WATER LEVEL (m) | AN7: Wellsite | AO7: REMARKS
B8: PLAN | C8: ACTUAL | D8: START | E8: FINISH | G8: RIG | H8: TYPE | I8: EASTING | J8: NORTHING | K8: ELV. | L8: EASTING | M8: NORTHING | N8: ELV. | O8: OPEN HOLE ( M ) | R8: RUN | S8: CORING ( M ) | Z8: BOR LOG ( M ) | AC8: E - LOG ( M )
K9: (M) | N9: (M) | O9: FROM | P9: TO | Q9: THICK | S9: FROM | T9: TO | U9: THICK | X9: DRILLING | Y9: LOGGING | Z9: FROM | AA9: TO | AB9: THICK | AC9: FROM | AD9: TO | AE9: THICK | AG9: FROM | AH9: TO | AI9: THICK
A10: 1 | B10: DH11_01 | C10: =Collar!A5 -> DH11_01 | D10: 43924 | E10: 43928 | F10: 11 | G10: AAS_02 | H10: JC_175 | I10: 359611 | J10: 9590552 | K10: 84 | L10: 359619.03 | M10: 9590558 | N10: 69.816 | O10: 0 | P10: 100 | Q10: =P10-O10 -> 100 | X10: 100 | Y10: 95.98 | AN10: BSW
R11: 0 | U11: =T11-S11 -> 0
U12: =T12-S12 -> 0 | Z12: 0 | AA12: 0 | AB12: =AA12-Z12 -> 0 | AC12: 27.62 | AD12: 28.6 | AE12: =AD12-AC12 -> 0.98 | AF12: LSD | AG12: =AC12 -> 27.62 | AH12: =AD12 -> 28.6 | AI12: =AH12-AG12 -> 0.98 | AJ12: =AB12/AI12*100 -> 0 | AK12: S7 | AL12: 0 | AO12: 0
AC13: 28.6 | AD13: 28.65 | AE13: =AD13-AC13 -> 0.05 | AG13: =AC13 -> 28.6 | AH13: =AD13 -> 28.65 | AI13: =AH13-AG13 -> 0.05 | AK13: PA
AC14: 28.65 | AD14: 29.2 | AE14: =AD14-AC14 -> 0.55 | AG14: =AC14 -> 28.65 | AH14: =AD14 -> 29.2 | AI14: =AH14-AG14 -> 0.55 | AK14: S7
AC15: 41.85 | AD15: 43.45 | AE15: =AD15-AC15 -> 1.6 | AG15: =AC15 -> 41.85 | AH15: =AD15 -> 43.45 | AI15: =AH15-AG15 -> 1.6 | AK15: S7A
AC16: 58.92 | AD16: 60.25 | AE16: =AD16-AC16 -> 1.33 | AG16: =AC16 -> 58.92 | AH16: =AD16 -> 60.25 | AI16: =AH16-AG16 -> 1.33 | AK16: S7B
AC17: 60.45 | AD17: 61.4 | AE17: =AD17-AC17 -> 0.95 | AG17: =AC17 -> 60.45 | AH17: =AD17 -> 61.4 | AI17: =AH17-AG17 -> 0.95 | AK17: S7B
AC18: 61.45 | AD18: 62.05 | AE18: =AD18-AC18 -> 0.6 | AG18: =AC18 -> 61.45 | AH18: =AD18 -> 62.05 | AI18: =AH18-AG18 -> 0.6 | AK18: S7B
AC19: 80.05 | AD19: 81.08 | AE19: =AD19-AC19 -> 1.03 | AG19: =AC19 -> 80.05 | AH19: =AD19 -> 81.08 | AI19: =AH19-AG19 -> 1.03 | AK19: S7C
U20: =T20-S20 -> 0 | AC20: 85.65 | AD20: 87.6 | AE20: =AD20-AC20 -> 1.95 | AG20: =AC20 -> 85.65 | AH20: =AD20 -> 87.6 | AI20: =AH20-AG20 -> 1.95 | AK20: S7D
Q21: =P21-O21 -> 0
S22: Core Recovery | U22: =SUM(U10:U21) -> 0 | V22: =SUM(V10:V21) -> 0 | W22: =V22/U22*100 -> #DIV/0! | X22: Log Rec. | Y22: =Y10/X10*100 -> 95.98

Sheet Sampling
B2: No | C2: Hole Id | D2: Sample Position | E2: Sample Number | F2: Drilling Depth | I2: Adjusted Depth | L2: Sampling Date | M2: Seam | N2: Remarks | R2: Sampling Library
F3: From | G3: To | H3: Length | I3: From | J3: To | K3: Length | R3: Code | S3: Description
R4: R | S4: Roof
B5: 1 | C5: =Collar!A5 -> DH11_01 | D5: Coal Body | E5: =BHC!AL12 -> 0 | F5: =BHC!Z12 -> 0 | G5: =BHC!AA12 -> 0 | H5: =G5-F5 -> 0 | I5: =BHC!AG12 -> 27.62 | J5: =BHC!AH12 -> 28.6 | K5: =J5-I5 -> 0.98 | M5: 0 | N5: =BHC!AO12 -> 0 | R5: CR | S5: Coal Roof
R6: CB | S6: Coal Body
R7: CBP | S7: Coal Body Parting
B8: NOTES: Untuk awal, bagian sampling ini nanti sy isi dulu. Pengambilan sample di lapangan lakukan secara ply by ply sesuai dengan SOP yang sudah dishare sebelumnya | R8: P | S8: Parting
C9: Ketika proses review sy akan atur ply mana saja yg dapat dicomposite | R9: CF | S9: Coal Floor
R10: F | S10: Floor

Sheet Library SLL
A1: Shift | D1: Lithology | G1: Qualifers | J1: Grain | M1: Sediment Structure | P1: Weathering | S1: Association
A2: D | B2: Day | D2: AW | E2: Andesite | G2: BA | H2: Banded | J2: BO | K2: Boulder | M2: AR | N2: Asymetric ripple marks | P2: DE | Q2: Decomposed | S2: BN | T2: Bands
A3: N | B3: Night | D3: BA | E3: Basalt | G3: CC | H3: Calcareous | J3: CB | K3: Cobble | M3: BA | N3: Banded | P3: CW | Q3: Completely weathered | S3: BP | T3: On bedding planes
A4: Log Basis | D4: BR | E4: Breccia | G4: CE | H4: Cement | J4: PB | K4: Pebble | M4: BI | N4: Bioturbation | P4: HW | Q4: Highly weathered | S4: CE | T4: Cement
A5: A | B5: Chip | D5: CA | E5: Calcite | G5: CL | H5: Clay | J5: GR | K5: Granular | M5: BU | N5: Burrows | P5: MW | Q5: Moderately weathered | S5: CT | T5: On cleats
A6: X | B6: Chip & Geophys. Log | D6: XC | E6: Carbonaceous CS | G6: CO | H6: Coaly | J6: VC | K6: Very coarse | M6: CU | N6: Coarsening upwards | P6: SW | Q6: Slightly weathered | S6: DS | T6: Disseminated
A7: C | B7: Core | D7: XM | E7: Carbonaceous MS | G7: FN | H7: Fine | J7: CO | K7: Coarse | M7: CF | N7: Compaction feature | P7: FR | Q7: Fresh rock | S7: JT | T7: On joints'
A8: V | B8: Core very broken | D8: XH | E8: Carbonaceous Shale | G8: LN | H8: Lateritic | J8: MD | K8: Med. Grained | M8: OC | N8: Cone in cone structure | P8: Mechanical State | S8: LM | T8: Laminaes
A9: L | B9: Core log | D9: CB | E9: Carbonate | G9: LI | H9: Lithic | J9: FN | K9: Fine | M9: XB | N9: Cross bedding | P9: S1 | Q9: Solid core | S9: LN | T9: Lenses
A10: G | B10: Geophysical Log | D10: CL | E10: Clay | G10: LM | H10: Lenses | J10: VF | K10: Very fine | M10: FB | N10: Fine Bedding | P10: S2 | Q10: Slightly broken core | S10: NO | T10: Nodules
A11: O | B11: Outcrop | D11: CS | E11: Clay Stone | G11: MA | H11: Matrix | M11: FV | N11: Fining upwards | P11: S3 | Q11: Broken core | S11: ST | T11: Staining
A12: S | B12: Shaft | D12: CO | E12: Coal Undifferentiated | G12: ML | H12: Marly | J12: Roundness | M12: FC | N12: Flute casts | P12: S4 | Q12: Fragmented core | S12: VE | T12: Veins
A13: T | B13: Trench | D13: CW | E13: Coal weathered | G13: MI | H13: Micaeous | J13: V | K13: Very angular | M13: GB | N13: Graded bedding | P13: BR | Q13: Brecciated | S13: Sediment Relationship
A14: Bit Type | D14: C1 | E14: Coal, >90% bright | G14: MD | H14: Muddy | J14: A | K14: Angular | M14: IR | N14: Irregular Bedding | P14: BE | Q14: Brittle | S14: BN | T14: With bands
A15: A | B15: Roller Bit | D15: C2 | E15: Coal, 60-90% bright | G15: PB | H15: Pebbly | J15: S | K15: Subangular | M15: LC | N15: Load Casts | P15: DH | Q15: Dense | S15: BU | T15: Towards base
A16: B | B16: Blade Bit | D16: C3 | E16: Coal, 40-60% bright | G16: PE | H16: Pelletoidal | J16: U | K16: Subrounded | M16: LM | N16: Laminae | P16: DO | Q16: Desintegrates on drying | S16: CU | T16: Coarsening up to
A17: D | B17: Diamond Coring Bit | D17: C4 | E17: Coal,10-40% bright | G17: QF | H17: Quartz Feldspatihic | J17: R | K17: Rounded | M17: LN | N17: Lenticular Bedding | P17: FI | Q17: Fissile | S17: CX | T17: With cobbles of
A18: H | B18: Hammer | D18: C5 | E18: Coal, <10% bright | G18: QL | H18: Quartz Lithic | J18: W | K18: Well rounded | M18: MB | N18: Massive Bedding | P18: FR | Q18: Fretted core | S18: FU | T18: Fining up to
A19: I | B19: Impreg | D19: ZC | E19: Coaly Clystone | G19: QZ | H19: Quartzose | M19: MF | N19: Microfaulting | P19: SH | Q19: Sheared | S19: IB | T19: Interbedded with
A20: L | B20: Single | D20: ZM | E20: Coaly Mudstone | G20: RS | H20: Resinious | J20: Sorting | M20: TD | N20: Tidal flat bedding | P20: SC | Q20: Sticky clay | S20: LC | T20: With load cacts of
A21: P | B21: PCD | D21: ZH | E21: Coaly Shale | G21: SA | H21: Sandy | J21: P | K21: Poorly sorted | M21: SR | N21: Symetrical ripple marks | P21: SF | Q21: Subfissile | S21: LM | T21: With laminase of
A22: S | B22: Step | D22: LA | E22: Laterite | G22: SC | H22: Slighty Carbonaceous | J22: M | K22: Moderately sorted | M22: NA | N22: Not Available | P22: TO | Q22: Tough | S22: LH | T22: With lenses of
A23: T | B23: Tungsten Coring Bit | D23: LG | E23: Lignite | G23: SL | H23: Silty | J23: W | K23: Well sorted | M23: Type Tec Structure | P23: MA | Q23: Massive | S23: MX | T23: With matrix of
A24: W | B24: Wingbit | D24: LT | E24: Limestone | G24: TC | H24: Striner of Coal | J24: B | K24: Bimodal sorting | M24: B | N24: Bedding planes | P24: Abundances Min & Fossil | S24: PB | T24: With pebbles of
A25: Hole Diameter | D25: SO | E25: Siderite | G25: RA | H25: Rare | M25: C | N25: With cleats | P25: A | Q25: Abundant | S25: TO | T25: Throughout
A26: BQ | D26: LS | E26: Shale Limestone | G26: TH | H26: Thin | J26: Porosity & Permeability | M26: F | N26: With Faults | P26: C | Q26: Common | S26: Ply
A27: HQ | D27: MM | E27: Metamorphic Rock | G27: TK | H27: Thick | J27: B | K27: Bad porosity | M27: R | N27: With fracture | P27: R | Q27: Rare | S27: 1 | T27: Ply 1
A28: NQ | D28: MS | E28: Mudstone | G28: YN | H28: Vitrinous | J28: M | K28: Medium Porosity | M28: J | N28: With joints | P28: S | Q28: Sparse | S28: 2 | T28: Ply 2
A29: PQ | D29: PY | E29: Pyrite | G29: WS | H29: Wisps | J29: G | K29: Good Porosity | M29: S | N29: With shearing | P29: Mineral & Fossil | S29: 3 | T29: Ply 3
A30: Hole Type | D30: SS | E30: Sandstone | G30: WY | H30: Woody | M30: V | N30: With veins | P30: BT | Q30: Bioturbation | S30: 4 | T30: Ply 4
A31: OH | B31: Open Hole | D31: SH | E31: Shale | G31: SD | H31: Sideritic | J31: Space Bedding | M31: NA | N31: Not Available | P31: BI | Q31: Bivalves | S31: 5 | T31: Ply 5
A32: FC | B32: Full core | D32: SL | E32: Siltstone | G32: Shade | J32: 1 | K32: Very thick (>1.0 m) | M32: Space Tec Structure | P32: BM | Q32: Black mica | S32: Seam
A33: TC | B33: Touch Core | D33: SO | E33: Soil | G33: A | H33: Light | J33: 2 | K33: Thick (0.3-1.0 m) | M33: 1 | N33: Very wide (>2.0m) | P33: BU | Q33: Burrows | S33: A | T33: Seam A
A34: Continuity | D34: CH | E34: Stony Coal | G34: B | H34: Medium | J34: 3 | K34: Medium (0.1-0.3 m) | M34: 2 | N34: Wide (0.6-2.0m) | P34: CA | Q34: Calcite | S34: B | T34: Seam B
A35: OH | B35: Open Hole | D35: TF | E35: Tuff | G35: C | H35: Dark | J35: 4 | K35: Thin (3-10 cm) | M35: 3 | N35: Moder wide (0.2-0.6m) | P35: XL | Q35: Carbonaceous laminae | S35: C | T35: Seam C
A36: R_ | B36: Running | D36: YD | E36: Undifferientate rock | G36: D | H36: Motled | J36: 5 | K36: Very Thin (1-3 cm) | M36: 4 | N36: Close (6-20cm) | P36: CB | Q36: Carbonate | S36: D | T36: Seam D
A37: Casing Type | D37: NL | E37: Not Logged | G37: Hue | J37: 6 | K37: Laminated (0.3-1cm) | M37: 5 | N37: Very Close (2-6cm) | P37: CH | Q37: Chlorite | S37: E | T37: Seam E
A38: PV | B38: PVC casing | D38: KL | E38: Core Loss | G38: B | H38: Brownish | J38: 7 | K38: Thinly lam (<0.3 cm) | M38: 6 | N38: Extremely Colse (<2cm) | P38: CF | Q38: Coaly fragments | S38: Sampling Library
A39: ST | B39: welded steel | D39: LC | E39: Lost Circulation | G39: E | H39: Greenish | J39: NA | K39: Not Available | M39: 7 | N39: Vertical/Subvertical | P39: CL | Q39: Coaly lamminae | S39: Code | T39: Description
A40: TS | B40: Treaded steel | D40: NK | E40: Not Cored | G40: G | H40: Greyish | J40: Separate Bedding | M40: NA | N40: Not Available | P40: CW | Q40: Coaly wisps | S40: R | T40: Roof
...
